Workbook

Sheet 入力
A1: 【入力フォーム】 このシートを上から埋めるだけで、共有シート・見積書が自動で出来上がります
A2: 黄色=入力欄(▼はリスト選択) / 緑=自動計算(触らない) / 例が入っています。上書きしてお使いください
A3: ■ 1. 基本情報
A4: 会社名 | B4: 田中産業株式会社
A5: 団体名 | B5: 田中産業 親睦会ご一行様
A6: ツアー名 | B6: 2026年度 社員親睦旅行
A7: 先方担当者 | B7: 田中 一郎 様(090-0000-0000)
A8: 利用開始日 | B8: 46249
A9: 利用終了日 | B9: 46250
A10: 人数(合計) | B10: 40
A11: 人数内訳メモ | B11: 大人40名
A12: 到着手段・時刻 | B12: 貸切バス 15:00着予定
A13: ステータス ▼ | B13: 確定
A14: 社内担当 | B14: セールス 清水
A15: コード略号(英字4) | B15: TANA
A16: ブロックコード | B16: =IF(OR(B8="",B15=""),"",TEXT(B8,"mmdd")&UPPER(B15)&"01") -> 0815TANA01
A17: 見積番号 | B17: Q-2026-0001
A18: 発行日 | B18: 46220
A19: 支払方法 ▼ | B19: 後日振込
A20: 見積有効期限 | B20: 46235
A21: ■ 2. 宿泊
A22: 宿泊有無 ▼ | B22: 宿泊あり
A23: 部屋構成 | B23: 和室×15室(1室2〜3名)
A24: C/I・C/O | B24: 15:00 / 10:00
A25: 宿泊特記 | B25: 1階希望3名(車椅子貸出1名)
A26: ■ 3. 食事(1行に 日付・区分・時刻・会場・内容・数量 をまとめて記入)
A27: 食事1 | B27: 8/15 夕食 18:00 鶴の間 宴会コース+飲放90分 40名
A28: 食事2 | B28: 8/16 朝食 7:00 レストラン 和洋バイキング 40名
A29: 食事3
A30: アレルギー(必須) | B30: 甲殻類3名(名簿は料飲へ送付済)/対応: 個別メニュー
A31: ■ 4. 宴会・会場
A32: 会場 ▼ | B32: 鶴の間
A33: 設営/本番/撤収 | B33: 17:00設営 / 18:00-20:00 / 21:00撤収
A34: レイアウト ▼ | B34: 円卓
A35: 機材・備品 | B35: マイク2・プロジェクター
A36: 進行メモ | B36: 19:00頃 社長表彰(照明・マイク)
A37: ■ 5. 送迎
A38: 往路 | B38: 8/15 上越妙高駅 14:30発 → ホテル(バス2台)
A39: 復路 | B39: 8/16 ホテル 10:00発 → 上越妙高駅
A40: ■ 6. 見積明細(最大10行。項目▼と単位▼はリスト選択)
...

Sheet 社内共有シート
A1: 団体案件 社内共有シート | E1: ブロックコード | F1: =IF(入力!B16="","",入力!B16) -> 0815TANA01
E2: 発行日 | F2: =IF(入力!B18="","",入力!B18) -> 46220
A3: ステータス | B3: =IF(入力!B13="","",入力!B13) -> 確定 | E3: 社内担当 | F3: =IF(入力!B14="","",入力!B14) -> セールス 清水
A4: ■ 基本情報
A5: 会社名 | B5: =IF(入力!B4="","",入力!B4) -> 田中産業株式会社 | E5: 利用期間 | F5: =IF(入力!B8="","",TEXT(入力!B8,"m/d")&" 〜 "&IF(入力!B9="","",TEXT(入力!B9,"m/d"))) -> 8/15 〜 8/16
A6: 団体名 | B6: =IF(入力!B5="","",入力!B5) -> 田中産業 親睦会ご一行様 | E6: 人数 | F6: =IF(入力!B10="","",入力!B10&"名 "&入力!B11) -> 40名 大人40名
A7: ツアー名 | B7: =IF(入力!B6="","",入力!B6) -> 2026年度 社員親睦旅行 | E7: 到着 | F7: =IF(入力!B12="","",入力!B12) -> 貸切バス 15:00着予定
A8: 先方担当 | B8: =IF(入力!B7="","",入力!B7) -> 田中 一郎 様(090-0000-0000) | E8: 支払方法 | F8: =IF(入力!B19="","",入力!B19) -> 後日振込
A9: ■ 宿泊
A10: 部屋構成 | B10: =IF(入力!B23="","",入力!B23) -> 和室×15室(1室2〜3名) | E10: C/I・C/O | F10: =IF(入力!B24="","",入力!B24) -> 15:00 / 10:00
A11: 宿泊特記 | B11: =IF(入力!B25="","",入力!B25) -> 1階希望3名(車椅子貸出1名)
A12: ■ 食事
A13: 食事1 | B13: =IF(入力!B27="","",入力!B27) -> 8/15 夕食 18:00 鶴の間 宴会コース+飲放90分 40名
A14: 食事2 | B14: =IF(入力!B28="","",入力!B28) -> 8/16 朝食 7:00 レストラン 和洋バイキング 40名
A15: 食事3 | B15: =IF(入力!B29="","",入力!B29)
A16: アレルギー | B16: =IF(入力!B30="","",入力!B30) -> 甲殻類3名(名簿は料飲へ送付済)/対応: 個別メニュー
A17: ■ 宴会・会場
A18: 会場 | B18: =IF(入力!B32="","",入力!B32) -> 鶴の間 | E18: 設営/撤収 | F18: =IF(入力!B33="","",入力!B33) -> 17:00設営 / 18:00-20:00 / 21:00撤収
A19: レイアウト | B19: =IF(入力!B34="","",入力!B34) -> 円卓 | E19: 機材 | F19: =IF(入力!B35="","",入力!B35) -> マイク2・プロジェクター
A20: 進行メモ | B20: =IF(入力!B36="","",入力!B36) -> 19:00頃 社長表彰(照明・マイク)
A21: ■ 送迎
A22: 往路 | B22: =IF(入力!B38="","",入力!B38) -> 8/15 上越妙高駅 14:30発 → ホテル(バス2台) | E22: 復路 | F22: =IF(入力!B39="","",入力!B39) -> 8/16 ホテル 10:00発 → 上越妙高駅
A23: ■ 料金・請求
A24: 見積合計 | B24: =IF(見積書!G31=0,"","¥"&TEXT(見積書!G31,"#,##0")&"(税込)") -> ¥976,100(税込) | E24: 請求状況
A25: ■ 部署確認欄(内容確認したらサイン)
A26: フロント | B26: 予約 | C26: セールス | D26: 料飲 | E26: 調理 | F26: 施設 | G26: 備考
A28: ■ 特記事項・引き継ぎメモ
A29: =IF(入力!A55="","",入力!A55) -> ・幹事の田中様は昨年もご利用(前回: 朝食会場の案内不足→今回は前日に案内掲示) ・お土産(地酒)40個を売店に取り置き(8/16朝 フロント渡し) ・雨天時はバス乗降を正面玄関ひさし下に変更

Sheet 見積書
B1: 御 見 積 書 | F1: 見積番号 | G1: =IF(入力!B17="","",入力!B17) -> Q-2026-0001
F2: 発行日 | G2: =IF(入力!B18="","",入力!B18) -> 46220
F3: ブロックコード | G3: =IF(入力!B16="","",入力!B16) -> 0815TANA01
A4: =IF(入力!B4="","",入力!B4&" 御中") -> 田中産業株式会社 御中 | F4: 【ロゴ】
A5: =IF(入力!B5="","",入力!B5) -> 田中産業 親睦会ご一行様
A6: =IF(入力!B6="","",入力!B6) -> 2026年度 社員親睦旅行 | F6: =マスタ!I2 -> (ホテル名を入力)
A7: =IF(入力!B7="","","ご担当: "&入力!B7) -> ご担当: 田中 一郎 様(090-0000-0000) | F7: =マスタ!I3 -> (住所・TELを入力)
A8: 下記のとおりお見積り申し上げます。 | F8: ="インボイス登録番号 "&マスタ!I4 -> インボイス登録番号 T0000000000000
F9: 担当: | G9: =マスタ!I5 -> 清水 祥太郎
A10: 件名 | C10: =IF(入力!B6<>"",入力!B6,IF(入力!B5<>"",入力!B5,入力!B4&"様")) -> 2026年度 社員親睦旅行 | F10: 御見積合計(税込)
A11: ご利用期間 | C11: =IF(入力!B8="","",TEXT(入力!B8,"yyyy/m/d")&" 〜 "&IF(入力!B9="","",TEXT(入力!B9,"m/d"))) -> 2026/8/15 〜 8/16 | F11: =G31 -> 976100
A12: ご利用人数 | C12: =IF(入力!B10="","",入力!B10&"名("&入力!B11&")") -> 40名(大人40名)
A13: お支払方法 | C13: =IF(入力!B19="","",入力!B19) -> 後日振込 | F13: 見積有効期限
F14: =IF(入力!B20="","",入力!B20) -> 46235
A15: No. | B15: 項目 | C15: 内容 | D15: 単価 | E15: 数量 | F15: 単位 | G15: 金額
A16: =IF(入力!B42="","",ROW()-15) -> 1 | B16: =IF(入力!A42="","",入力!A42) -> 宿泊 | C16: =IF(入力!B42="","",入力!B42) -> 1泊2食付プラン(和室) | D16: =IF(入力!C42="","",入力!C42) -> 15000 | E16: =IF(入力!D42="","",入力!D42) -> 40 | F16: =IF(入力!E42="","",入力!E42) -> 名 | G16: =IF(COUNT(入力!C42,入力!D42)<2,"",入力!C42*入力!D42) -> 600000
A17: =IF(入力!B43="","",ROW()-15) -> 2 | B17: =IF(入力!A43="","",入力!A43) -> 宴会 | C17: =IF(入力!B43="","",入力!B43) -> 宴会場使用料(鶴の間 18:00-20:00) | D17: =IF(入力!C43="","",入力!C43) -> 50000 | E17: =IF(入力!D43="","",入力!D43) -> 1 | F17: =IF(入力!E43="","",入力!E43) -> 式 | G17: =IF(COUNT(入力!C43,入力!D43)<2,"",入力!C43*入力!D43) -> 50000
A18: =IF(入力!B44="","",ROW()-15) -> 3 | B18: =IF(入力!A44="","",入力!A44) -> 料飲 | C18: =IF(入力!B44="","",入力!B44) -> 飲み放題プラン 90分 | D18: =IF(入力!C44="","",入力!C44) -> 2500 | E18: =IF(入力!D44="","",入力!D44) -> 40 | F18: =IF(入力!E44="","",入力!E44) -> 名 | G18: =IF(COUNT(入力!C44,入力!D44)<2,"",入力!C44*入力!D44) -> 100000
A19: =IF(入力!B45="","",ROW()-15) -> 4 | B19: =IF(入力!A45="","",入力!A45) -> 送迎 | C19: =IF(入力!B45="","",入力!B45) -> 貸切バス送迎(上越妙高駅⇔ホテル 往復) | D19: =IF(入力!C45="","",入力!C45) -> 30000 | E19: =IF(入力!D45="","",入力!D45) -> 2 | F19: =IF(入力!E45="","",入力!E45) -> 台 | G19: =IF(COUNT(入力!C45,入力!D45)<2,"",入力!C45*入力!D45) -> 60000
A20: =IF(入力!B46="","",ROW()-15) | B20: =IF(入力!A46="","",入力!A46) | C20: =IF(入力!B46="","",入力!B46) | D20: =IF(入力!C46="","",入力!C46) | E20: =IF(入力!D46="","",入力!D46) | F20: =IF(入力!E46="","",入力!E46) | G20: =IF(COUNT(入力!C46,入力!D46)<2,"",入力!C46*入力!D46)
A21: =IF(入力!B47="","",ROW()-15) | B21: =IF(入力!A47="","",入力!A47) | C21: =IF(入力!B47="","",入力!B47) | D21: =IF(入力!C47="","",入力!C47) | E21: =IF(入力!D47="","",入力!D47) | F21: =IF(入力!E47="","",入力!E47) | G21: =IF(COUNT(入力!C47,入力!D47)<2,"",入力!C47*入力!D47)
A22: =IF(入力!B48="","",ROW()-15) | B22: =IF(入力!A48="","",入力!A48) | C22: =IF(入力!B48="","",入力!B48) | D22: =IF(入力!C48="","",入力!C48) | E22: =IF(入力!D48="","",入力!D48) | F22: =IF(入力!E48="","",入力!E48) | G22: =IF(COUNT(入力!C48,入力!D48)<2,"",入力!C48*入力!D48)
A23: =IF(入力!B49="","",ROW()-15) | B23: =IF(入力!A49="","",入力!A49) | C23: =IF(入力!B49="","",入力!B49) | D23: =IF(入力!C49="","",入力!C49) | E23: =IF(入力!D49="","",入力!D49) | F23: =IF(入力!E49="","",入力!E49) | G23: =IF(COUNT(入力!C49,入力!D49)<2,"",入力!C49*入力!D49)
A24: =IF(入力!B50="","",ROW()-15) | B24: =IF(入力!A50="","",入力!A50) | C24: =IF(入力!B50="","",入力!B50) | D24: =IF(入力!C50="","",入力!C50) | E24: =IF(入力!D50="","",入力!D50) | F24: =IF(入力!E50="","",入力!E50) | G24: =IF(COUNT(入力!C50,入力!D50)<2,"",入力!C50*入力!D50)
A25: =IF(入力!B51="","",ROW()-15) | B25: =IF(入力!A51="","",入力!A51) | C25: =IF(入力!B51="","",入力!B51) | D25: =IF(入力!C51="","",入力!C51) | E25: =IF(入力!D51="","",入力!D51) | F25: =IF(入力!E51="","",入力!E51) | G25: =IF(COUNT(入力!C51,入力!D51)<2,"",入力!C51*入力!D51)
D26: 小計 | G26: =SUM(G16:G25) -> 810000
D27: サービス料(10%) | G27: =ROUND(G26*0.1,0) -> 81000
D28: 消費税(10%) | G28: =ROUND((G26+G27)*0.1,0) -> 89100
A29: ※入湯税=150円×宿泊人数×泊数(入力シートで) | D29: 入湯税 | G29: =N(入力!B52) -> 6000
D30: お値引き | G30: =N(入力!B53) -> -10000
D31: 御見積合計(税込) | G31: =G26+G27+G28+G29+G30 -> 976100
A33: 備考
A37: ※このシートは自動生成(緑セル)。個別調整は備考欄(黄色)か、値を直接上書きしてください。

Sheet マスタ
A1: ステータス | B1: 支払方法 | C1: 会場 | D1: レイアウト | E1: 明細項目 | F1: 単位 | H1: ▼ホテル情報(見積書の発行者欄に入ります)
A2: 引合 | B2: 現地現金 | C2: 鶴の間 | D2: シアター | E2: 宿泊 | F2: 名 | H2: ホテル名 | I2: (ホテル名を入力)
A3: 仮予約 | B3: 現地カード | C3: 亀の間 | D3: スクール | E3: 宴会 | F3: 式 | H3: 住所・TEL | I3: (住所・TELを入力)
A4: 確定 | B4: 後日振込 | C4: レストラン | D4: 円卓 | E4: 料飲 | F4: 台 | H4: インボイス番号 | I4: T0000000000000
A5: 実施済 | B5: エージェント精算 | C5: ラウンジ | D5: 立食 | E5: 送迎 | F5: 室 | H5: 担当者 | I5: 清水 祥太郎
A6: 請求済 | C6: 多目的ホール | E6: その他 | F6: 個
A7: 入金済 | F7: 本
A8: キャンセル
A10: 選択肢はこの列を書き換えれば入力シートの▼リストに反映されます。行の追加は各列の続きに。
